<?xml version="1.0"?>
<sdf version="1.6">
    <model name="X1">
        <enable_wind>1</enable_wind>
        <static>0</static>
        <link name="base_link">
            <inertial>
                <pose frame="">0.0 0.0 0.062 0 0 0</pose>
                <mass>46.034</mass>
                <inertia>
                    <ixx>0.613201</ixx>
                    <ixy>-0.0236401</ixy>
                    <ixz>-0.1197</ixz>
                    <iyy>1.7496</iyy>
                    <iyz>-0.00154411</iyz>
                    <izz>2.0406</izz>
                </inertia>
            </inertial>
            <collision name="base_link_collision">
                <pose frame="">0 0 0.12 0 0 0</pose>
                <geometry>
                    <box>
                        <size>0.9874 0.5709 0.05</size>
                    </box>
                </geometry>
            </collision>
            <collision name="base_link_collision_bottom">
                <pose frame="">0 0 0.046 0 0 0</pose>
                <geometry>
                    <box>
                        <size>0.80 0.5709 0.095</size>
                    </box>
                </geometry>
            </collision>
            <collision name="base_link_collision_1">
                <pose frame="">0 0 0.185625 0 0 0</pose>
                <geometry>
                    <box>
                        <size>0.78992 0.5709 0.12375</size>
                    </box>
                </geometry>
            </collision>
            <collision name="top_plate_collision">
                <pose frame="">0.0812 0 0.245 0 0 0</pose>
                <geometry>
                    <mesh>
                        <uri>model://X1/meshes/top_plate.dae</uri>
                    </mesh>
                </geometry>
            </collision>
            <collision name="top_plate_collision_2">
                <pose frame="">0.0812 0 0.245 0 0 0</pose>
                <geometry>
                    <box>
                        <size>0.32 0.41 0.09</size>
                    </box>
                </geometry>
            </collision>
            <visual name="base_link_visual">
                <pose frame="">0 0 0 0 0 -3.14159</pose>
                <geometry>
                    <mesh>
                        <uri>model://X1/meshes/chassis.dae</uri>
                    </mesh>
                </geometry>
            </visual>
            <visual name="marker_visual_1">
                <pose frame="">0.066047 0.212211 0.209188 -3.14159 1.57079 -1.60259</pose>
                <geometry>
                    <mesh>
                        <uri>model://X1/meshes/led.dae</uri>
                    </mesh>
                </geometry>
            </visual>
            <visual name="marker_visual_2">
                <pose frame="">-0.066047 0.212211 0.209188 -3.14159 1.57079 -1.60259</pose>
                <geometry>
                    <mesh>
                        <uri>model://X1/meshes/led.dae</uri>
                    </mesh>
                </geometry>
            </visual>
            <visual name="marker_visual_3">
                <pose frame="">-0.42493 0 0.209188 3.14159 1.57079 7e-06</pose>
                <geometry>
                    <mesh>
                        <uri>model://X1/meshes/led.dae</uri>
                    </mesh>
                </geometry>
            </visual>
            <visual name="marker_visual_4">
                <pose frame="">-0.42493 0.13619 0.209188 3.14159 1.57079 7e-06</pose>
                <geometry>
                    <mesh>
                        <uri>model://X1/meshes/led.dae</uri>
                    </mesh>
                </geometry>
            </visual>
            <visual name="marker_visual_5">
                <pose frame="">-0.42493 -0.13619 0.209188 3.14159 1.57079 7e-06</pose>
                <geometry>
                    <mesh>
                        <uri>model://X1/meshes/led.dae</uri>
                    </mesh>
                </geometry>
            </visual>
            <visual name="marker_visual_6">
                <pose frame="">0.066047 -0.212211 0.209188 3.14159 1.57079 1.60259</pose>
                <geometry>
                    <mesh>
                        <uri>model://X1/meshes/led.dae</uri>
                    </mesh>
                </geometry>
            </visual>
            <visual name="marker_visual_7">
                <pose frame="">-0.066047 -0.212211 0.209188 3.14159 1.57079 1.60259</pose>
                <geometry>
                    <mesh>
                        <uri>model://X1/meshes/led.dae</uri>
                    </mesh>
                </geometry>
            </visual>
            <visual name="top_plate_visual">
                <pose frame="">0.0812 0 0.245 0 0 0</pose>
                <geometry>
                    <mesh>
                        <uri>model://X1/meshes/top_plate_new.dae</uri>
                    </mesh>
                </geometry>
            </visual>
       

        </link>
        <link name="front_left_wheel">
            <pose frame="">0.256 0.2854 0.03282 0 0 0</pose>
            <inertial>
                <mass>2.637</mass>
                <inertia>
                    <ixx>0.02467</ixx>
                    <ixy>0</ixy>
                    <ixz>0</ixz>
                    <iyy>0.04411</iyy>
                    <iyz>0</iyz>
                    <izz>0.02467</izz>
                </inertia>
            </inertial>
            <collision name="collision">
                <pose frame="">0 0 0 -1.5707963267948966 0 0</pose>
                <geometry>
                    <cylinder>
                        <length>0.1143</length>
                        <radius>0.1651</radius>
                    </cylinder>
                </geometry>
                <surface>
                    <friction>
                        <ode>
                            <mu>0.5</mu>
                            <mu2>1</mu2>
                            <slip1>0.00062</slip1>
                            <slip2>0</slip2>
                            <fdir1>0 0 1</fdir1>
                        </ode>
                    </friction>
                </surface>
            </collision>
            <visual name="visual">
                <geometry>
                    <mesh>
                        <uri>model://X1/meshes/wheel.dae</uri>
                    </mesh>
                </geometry>
            </visual>
        </link>
        <joint name="front_left_wheel_joint" type="revolute">
            <parent>base_link</parent>
            <child>front_left_wheel</child>
            <axis>
                <xyz>0 1 0</xyz>
                <limit>
                    <lower>-1.79769e+308</lower>
                    <upper>+1.79769e+308</upper>
                </limit>
            </axis>
        </joint>
        <link name="front_right_wheel">
            <pose frame="">0.256 -0.2854 0.03282 0 0 0</pose>
            <inertial>
                <mass>2.637</mass>
                <inertia>
                    <ixx>0.02467</ixx>
                    <ixy>0</ixy>
                    <ixz>0</ixz>
                    <iyy>0.04411</iyy>
                    <iyz>0</iyz>
                    <izz>0.02467</izz>
                </inertia>
            </inertial>
            <collision name="collision">
                <pose frame="">0 0 0 -1.5707963267948966 0 0</pose>
                <geometry>
                    <cylinder>
                        <length>0.1143</length>
                        <radius>0.1651</radius>
                    </cylinder>
                </geometry>
                <surface>
                    <friction>
                        <ode>
                            <mu>0.5</mu>
                            <mu2>1</mu2>
                            <slip1>0.00062</slip1>
                            <slip2>0</slip2>
                            <fdir1>0 0 1</fdir1>
                        </ode>
                    </friction>
                </surface>
            </collision>
            <visual name="visual">
                <geometry>
                    <mesh>
                        <uri>model://X1/meshes/wheel.dae</uri>
                    </mesh>
                </geometry>
            </visual>
        </link>
        <joint name="front_right_wheel_joint" type="revolute">
            <child>front_right_wheel</child>
            <parent>base_link</parent>
            <axis>
                <xyz>0 1 0</xyz>
                <limit>
                    <lower>-1.79769e+308</lower>
                    <upper>+1.79769e+308</upper>
                </limit>
            </axis>
        </joint>
        <link name="rear_left_wheel">
            <pose frame="">-0.256 0.2854 0.03282 0 0 0</pose>
            <inertial>
                <mass>2.637</mass>
                <inertia>
                    <ixx>0.02467</ixx>
                    <ixy>0</ixy>
                    <ixz>0</ixz>
                    <iyy>0.04411</iyy>
                    <iyz>0</iyz>
                    <izz>0.02467</izz>
                </inertia>
            </inertial>
            <collision name="collision">
                <pose frame="">0 0 0 -1.5707963267948966 0 0</pose>
                <geometry>
                    <cylinder>
                        <length>0.1143</length>
                        <radius>0.1651</radius>
                    </cylinder>
                </geometry>
                <surface>
                    <friction>
                        <ode>
                            <mu>0.5</mu>
                            <mu2>1</mu2>
                            <slip1>0.00062</slip1>
                            <slip2>0</slip2>
                            <fdir1>0 0 1</fdir1>
                        </ode>
                    </friction>
                </surface>
            </collision>
            <visual name="visual">
                <geometry>
                    <mesh>
                        <uri>model://X1/meshes/wheel.dae</uri>
                    </mesh>
                </geometry>
            </visual>
        </link>
        <joint name="rear_left_wheel_joint" type="revolute">
            <parent>base_link</parent>
            <child>rear_left_wheel</child>
            <axis>
                <xyz>0 1 0</xyz>
                <limit>
                    <lower>-1.79769e+308</lower>
                    <upper>+1.79769e+308</upper>
                </limit>
            </axis>
        </joint>
        <link name="rear_right_wheel">
            <pose frame="">-0.256 -0.2854 0.03282 0 0 0</pose>
            <inertial>
                <mass>2.637</mass>
                <inertia>
                    <ixx>0.02467</ixx>
                    <ixy>0</ixy>
                    <ixz>0</ixz>
                    <iyy>0.04411</iyy>
                    <iyz>0</iyz>
                    <izz>0.02467</izz>
                </inertia>
            </inertial>
            <collision name="collision">
                <pose frame="">0 0 0 -1.5707963267948966 0 0</pose>
                <geometry>
                    <cylinder>
                        <length>0.1143</length>
                        <radius>0.1651</radius>
                    </cylinder>
                </geometry>
                <surface>
                    <friction>
                        <ode>
                            <mu>0.5</mu>
                            <mu2>1</mu2>
                            <slip1>0.00062</slip1>
                            <slip2>0</slip2>
                            <fdir1>0 0 1</fdir1>
                        </ode>
                    </friction>
                </surface>
            </collision>
            <visual name="visual">
                <geometry>
                    <mesh>
                        <uri>model://X1/meshes/wheel.dae</uri>
                    </mesh>
                </geometry>
            </visual>
        </link>
        <joint name="rear_right_wheel_joint" type="revolute">
            <child>rear_right_wheel</child>
            <parent>base_link</parent>
            <axis>
                <xyz>0 1 0</xyz>
                <limit>
                    <lower>-1.79769e+308</lower>
                    <upper>+1.79769e+308</upper>
                </limit>
            </axis>
        </joint>
        <plugin
            filename="gz-sim-diff-drive-system"
            name="gz::sim::systems::DiffDrive">
            <left_joint>front_left_wheel_joint</left_joint>
            <left_joint>rear_left_wheel_joint</left_joint>
            <right_joint>front_right_wheel_joint</right_joint>
            <right_joint>rear_right_wheel_joint</right_joint>
            <wheel_separation>0.5708</wheel_separation>
            <wheel_radius>0.1651</wheel_radius>
            <odom_publish_frequency>1</odom_publish_frequency>
            <topic>cmd_rover_vel</topic>
        </plugin>
        <plugin
            name="gz::sim::systems::OdometryPublisher"
            filename="gz-sim-odometry-publisher-system">
            <topic>/landing_pad/odom</topic>
            <odom_frame_id>map</odom_frame_id>
            <child_frame_id>base_link</child_frame_id>
            <world_frame>true</world_frame>
            <publish_odom>true</publish_odom>
        </plugin>
    </model>
</sdf>
